2025-09-12 09:40:04,643 (INFO)- django.utils.autoreload- Watching for file changes with StatReloader
2025-09-12 09:41:34,462 (INFO)- django.utils.autoreload- /home/prince/projects/Social/src/social/settings.py changed, reloading.
2025-09-12 09:41:34,841 (INFO)- django.utils.autoreload- Watching for file changes with StatReloader
2025-09-12 09:50:00,454 (INFO)- django.utils.autoreload- /home/prince/projects/Social/src/core/auth/password_service.py changed, reloading.
2025-09-12 09:50:00,827 (INFO)- django.utils.autoreload- Watching for file changes with StatReloader
2025-09-12 09:50:42,260 (INFO)- django.utils.autoreload- /home/prince/projects/Social/src/core/auth/password_service.py changed, reloading.
2025-09-12 09:50:42,623 (INFO)- django.utils.autoreload- Watching for file changes with StatReloader
2025-09-12 09:52:31,707 (INFO)- django.utils.autoreload- /home/prince/projects/Social/src/core/auth/password_service.py changed, reloading.
2025-09-12 09:52:32,087 (INFO)- django.utils.autoreload- Watching for file changes with StatReloader
2025-09-12 09:53:24,889 (INFO)- django.utils.autoreload- /home/prince/projects/Social/src/core/views/auth_view.py changed, reloading.
2025-09-12 09:53:25,265 (INFO)- django.utils.autoreload- Watching for file changes with StatReloader
2025-09-12 09:54:51,289 (WARNING)- django.request- Method Not Allowed: /api/token/refresh
2025-09-12 09:54:57,695 (ERROR)- django.request- Internal Server Error: /api/token/refresh
Traceback (most recent call last):
  File "/home/prince/projects/Social/.venv/lib/python3.12/site-packages/django/core/handlers/exception.py", line 55, in inner
    response = get_response(request)
               ^^^^^^^^^^^^^^^^^^^^^
  File "/home/prince/projects/Social/.venv/lib/python3.12/site-packages/django/core/handlers/base.py", line 197, in _get_response
    response = wrapped_callback(request, *callback_args, **callback_kwargs)
               ^^^^^^^^^^^^^^^^^^^^^^^^^^^^^^^^^^^^^^^^^^^^^^^^^^^^^^^^^^^^
  File "/home/prince/projects/Social/.venv/lib/python3.12/site-packages/django/views/decorators/csrf.py", line 65, in _view_wrapper
    return view_func(request, *args, **kwargs)
           ^^^^^^^^^^^^^^^^^^^^^^^^^^^^^^^^^^^
  File "/home/prince/projects/Social/.venv/lib/python3.12/site-packages/django/views/generic/base.py", line 105, in view
    return self.dispatch(request, *args, **kwargs)
           ^^^^^^^^^^^^^^^^^^^^^^^^^^^^^^^^^^^^^^^
  File "/home/prince/projects/Social/.venv/lib/python3.12/site-packages/rest_framework/views.py", line 515, in dispatch
    response = self.handle_exception(exc)
               ^^^^^^^^^^^^^^^^^^^^^^^^^^
  File "/home/prince/projects/Social/.venv/lib/python3.12/site-packages/rest_framework/views.py", line 475, in handle_exception
    self.raise_uncaught_exception(exc)
  File "/home/prince/projects/Social/.venv/lib/python3.12/site-packages/rest_framework/views.py", line 486, in raise_uncaught_exception
    raise exc
  File "/home/prince/projects/Social/.venv/lib/python3.12/site-packages/rest_framework/views.py", line 512, in dispatch
    response = handler(request, *args, **kwargs)
               ^^^^^^^^^^^^^^^^^^^^^^^^^^^^^^^^^
  File "/home/prince/projects/Social/.venv/lib/python3.12/site-packages/rest_framework_simplejwt/views.py", line 46, in post
    serializer.is_valid(raise_exception=True)
  File "/home/prince/projects/Social/.venv/lib/python3.12/site-packages/rest_framework/serializers.py", line 225, in is_valid
    self._validated_data = self.run_validation(self.initial_data)
                           ^^^^^^^^^^^^^^^^^^^^^^^^^^^^^^^^^^^^^^
  File "/home/prince/projects/Social/.venv/lib/python3.12/site-packages/rest_framework/serializers.py", line 447, in run_validation
    value = self.validate(value)
            ^^^^^^^^^^^^^^^^^^^^
  File "/home/prince/projects/Social/.venv/lib/python3.12/site-packages/rest_framework_simplejwt/serializers.py", line 116, in validate
    user := get_user_model().objects.get(
            ^^^^^^^^^^^^^^^^^^^^^^^^^^^^^
  File "/home/prince/projects/Social/.venv/lib/python3.12/site-packages/django/db/models/manager.py", line 87, in manager_method
    return getattr(self.get_queryset(), name)(*args, **kwargs)
           ^^^^^^^^^^^^^^^^^^^^^^^^^^^^^^^^^^^^^^^^^^^^^^^^^^^
  File "/home/prince/projects/Social/.venv/lib/python3.12/site-packages/django/db/models/query.py", line 633, in get
    raise self.model.DoesNotExist(
django.contrib.auth.models.User.DoesNotExist: User matching query does not exist.
2025-09-12 09:59:02,795 (INFO)- django.utils.autoreload- Watching for file changes with StatReloader
2025-09-12 10:00:21,017 (WARNING)- django.request- Method Not Allowed: /api/token/
2025-09-12 10:05:29,815 (INFO)- django.utils.autoreload- /home/prince/projects/Social/src/core/auth/auth.py changed, reloading.
2025-09-12 10:05:30,212 (INFO)- django.utils.autoreload- Watching for file changes with StatReloader
2025-09-12 10:05:54,787 (INFO)- core.auth.auth- Validation Failed: wrong password
2025-09-12 10:05:55,341 (INFO)- core.auth.auth- Validation Failed: wrong password
2025-09-12 10:05:55,917 (INFO)- core.auth.auth- Validation Failed: wrong password
2025-09-12 10:07:34,828 (INFO)- django.utils.autoreload- /home/prince/projects/Social/src/social/settings.py changed, reloading.
2025-09-12 10:07:51,233 (INFO)- core.auth.auth- Validation Failed: wrong password
2025-09-12 10:10:14,203 (INFO)- core.auth.auth- Validation Failed: wrong password
2025-09-12 10:10:47,832 (INFO)- core.auth.auth- Validation Failed: wrong password
2025-09-12 10:14:22,307 (INFO)- core.auth.auth- Validation Failed: wrong password
2025-09-12 10:14:52,994 (INFO)- core.auth.auth- Validation Failed: wrong password
2025-09-12 10:14:53,556 (INFO)- core.auth.auth- Validation Failed: wrong password
2025-09-12 10:14:54,123 (INFO)- core.auth.auth- Validation Failed: wrong password
2025-09-12 10:27:08,878 (INFO)- core.auth.auth- Validation Failed: wrong password
2025-09-12 10:27:09,454 (INFO)- core.auth.auth- Validation Failed: wrong password
2025-09-12 10:27:10,028 (INFO)- core.auth.auth- Validation Failed: wrong password
2025-09-12 10:37:33,758 (INFO)- core.auth.auth- Validation Sucess : user.id=1 logged in
2025-09-12 10:37:34,339 (INFO)- core.auth.auth- Validation Sucess : user.id=1 logged in
2025-09-12 10:37:34,915 (INFO)- core.auth.auth- Validation Sucess : user.id=1 logged in
2025-09-12 15:44:39,490 (INFO)- core.auth.password_service- Credential created for user.id=3
2025-09-12 15:47:02,812 (INFO)- core.auth.auth- Validation Failed: wrong password
2025-09-12 15:49:53,126 (INFO)- core.auth.auth- Validation Failed: wrong password
2025-09-12 15:52:49,180 (INFO)- core.auth.auth- Validation Failed: wrong password
2025-09-12 15:53:04,126 (INFO)- core.auth.auth- Validation Sucess : user.id=3 logged in
2025-09-12 15:53:04,562 (INFO)- core.auth.auth- Validation Sucess : user.id=3 logged in
2025-09-12 15:54:01,213 (INFO)- core.auth.auth- Validation Sucess : user.id=3 logged in
2025-09-12 15:54:01,669 (INFO)- core.auth.auth- Validation Sucess : user.id=3 logged in
2025-09-12 16:02:48,259 (INFO)- core.views.auth_view- 123 with email 123@123.com
